Workbook

Sheet Cronograma V2
A1: Cronograma CBS 2027
A2: Reforma Tributária
A3: Última atualização | D3: 46304
E4: Previsto | H4: Real
A5: ID | B5: Marco | C5: Atividade | D5: Responsável | E5: Início | F5: Término | G5: Dias úteis | H5: Início | I5: Término | J5: Status | K5: Observação | L5: Frente
C6: Cronograma geral CBS 2027 | D6: - | E6: =MIN(E7:E132) -> 46266 | F6: =MAX(F7:F132) -> 46477 | G6: =IF(OR(E6="",F6=""),"",NETWORKDAYS(E6,F6,Feriados!$A$2:$A$9)) -> 145
A7: 1 | C7: Planejamento - Tarefa 101363 | E7: =MIN(E8:E19) -> 46288 | F7: =MAX(F8:F19) -> 46346 | G7: =IF(OR(E7="",F7=""),"",NETWORKDAYS(E7,F7,Feriados!$A$2:$A$9)) -> 40 | H7: 46288 | I7: 46297
A8: 1.1 | B8: S | C8: Confirmar a assinatura do contrato da JP Balaban | D8: Kairon Riguete | E8: 46296 | F8: 46310 | G8: =IF(OR(E8="",F8=""),"",NETWORKDAYS(E8,F8,Feriados!$A$2:$A$9)) -> 10 | J8: Não iniciado | L8: 9. Governança/PMO
A9: 1.2 | B9: N | C9: Realizar agendamento semanal de reuniões com os principais envolvidos | D9: Michael Albertoni | E9: 46290 | F9: 46290 | G9: =IF(OR(E9="",F9=""),"",NETWORKDAYS(E9,F9,Feriados!$A$2:$A$9)) -> 1 | H9: 46290 | I9: 46290 | J9: Concluído | L9: 9. Governança/PMO
A10: 1.3 | B10: S | C10: Validar cronograma com o Kairon | D10: Michael Albertoni | E10: 46300 | F10: 46305 | G10: =IF(OR(E10="",F10=""),"",NETWORKDAYS(E10,F10,Feriados!$A$2:$A$9)) -> 5 | J10: Não iniciado | L10: 9. Governança/PMO
A11: 1.4 | B11: N | C11: Revisar a escala de férias de fim de ano das pessoas chave | D11: Michael Albertoni | E11: 46296 | F11: 46346 | G11: =IF(OR(E11="",F11=""),"",NETWORKDAYS(E11,F11,Feriados!$A$2:$A$9)) -> 34 | J11: Não iniciado | K11: Considerar o conflito entre férias coletivas a partir de 20/12 e a virada de regime (levantado na reunião) A Eliandra não para na virada; de 18/11 a 30/11 atende só parcialmente | L11: 9. Governança/PMO
A12: 1.5 | B12: N | C12: Revisar cronograma com o dpto de controladoria e Fiscal | D12: Michael Albertoni | E12: 46288 | F12: 46288 | G12: =IF(OR(E12="",F12=""),"",NETWORKDAYS(E12,F12,Feriados!$A$2:$A$9)) -> 1 | H12: 46288 | I12: 46288 | J12: Concluído | L12: 9. Governança/PMO
A13: 1.6 | B13: N | C13: Revisar o cronograma com o dpto de contratos | D13: Michael Albertoni | E13: 46289 | F13: 46289 | G13: =IF(OR(E13="",F13=""),"",NETWORKDAYS(E13,F13,Feriados!$A$2:$A$9)) -> 1 | H13: 46289 | I13: 46289 | J13: Concluído | L13: 9. Governança/PMO
A14: 1.7 | B14: N | C14: Revisar o cronograma com o dpto Financeiro | D14: Michael Albertoni | E14: 46289 | F14: 46289 | G14: =IF(OR(E14="",F14=""),"",NETWORKDAYS(E14,F14,Feriados!$A$2:$A$9)) -> 1 | H14: 46289 | I14: 46289 | J14: Concluído | L14: 9. Governança/PMO
A15: 1.8 | B15: N | C15: Revisar o cronograma com o dpto de RH | D15: Michael Albertoni | E15: 46304 | F15: 46304 | G15: =IF(OR(E15="",F15=""),"",NETWORKDAYS(E15,F15,Feriados!$A$2:$A$9)) -> 1 | J15: Não iniciado | L15: 9. Governança/PMO
A16: 1.9 | B16: N | C16: Revisar o cronograma com o dpto de Supply Chain (Suprimentos e Frotas) | D16: Michael Albertoni | E16: 46293 | F16: 46293 | G16: =IF(OR(E16="",F16=""),"",NETWORKDAYS(E16,F16,Feriados!$A$2:$A$9)) -> 1 | H16: 46293 | I16: 46293 | J16: Concluído | L16: 9. Governança/PMO
A17: 1.10 | B17: N | C17: Revisar o cronograma com o dpto de T.I | D17: Michael Albertoni | E17: 46293 | F17: 46293 | G17: =IF(OR(E17="",F17=""),"",NETWORKDAYS(E17,F17,Feriados!$A$2:$A$9)) -> 1 | H17: 46293 | I17: 46293 | J17: Concluído | L17: 9. Governança/PMO
A18: 1.11 | B18: N | C18: Revisar o cronograma com a Contabilidade | D18: Michael Albertoni | E18: 46295 | F18: 46295 | G18: =IF(OR(E18="",F18=""),"",NETWORKDAYS(E18,F18,Feriados!$A$2:$A$9)) -> 1 | H18: 46297 | I18: 46297 | J18: Concluído | L18: 9. Governança/PMO
A19: 1.12 | B19: N | C19: Aprovar cronograma e modelo de status do projeto com o patrocinador | D19: Vitória Thums | E19: 46311 | F19: 46311 | G19: =IF(OR(E19="",F19=""),"",NETWORKDAYS(E19,F19,Feriados!$A$2:$A$9)) -> 1 | J19: Não iniciado | L19: 9. Governança/PMO
A20: 2 | C20: Parametrização do ERP Senior - Tarefa 102141 | E20: =MIN(E21:E62) -> 46286 | F20: =MAX(F21:F62) -> 46386 | G20: =IF(OR(E20="",F20=""),"",NETWORKDAYS(E20,F20,Feriados!$A$2:$A$9)) -> 69 | H20: 46286 | I20: 46301
A21: 2.1 | B21: N | C21: Confirmar a build do ERP, a versão do eDocs e o layout 2.00 da NFS-e | D21: Pablo e Kelvin | E21: 46286 | F21: 46290 | G21: =IF(OR(E21="",F21=""),"",NETWORKDAYS(E21,F21,Feriados!$A$2:$A$9)) -> 5 | H21: 46286 | I21: 46290 | J21: Concluído | L21: 4. TI/DF-e
A22: 2.2 | B22: N | C22: Atualizar o ERP e o eDocs com a correção da Senior para as notas de devolução | D22: Pablo e Kelvin | E22: 46291 | F22: 46291 | G22: =IF(OR(E22="",F22=""),"",NETWORKDAYS(E22,F22,Feriados!$A$2:$A$9)) -> 0 | H22: 46291 | I22: 46291 | J22: Concluído | L22: 4. TI/DF-e
A23: 2.3 | B23: N | C23: Mapear os municípios de emissão e a situação de homologação com a Reforma | D23: Pablo e Kelvin | E23: 46286 | F23: 46290 | G23: =IF(OR(E23="",F23=""),"",NETWORKDAYS(E23,F23,Feriados!$A$2:$A$9)) -> 5 | H23: 46286 | I23: 46290 | J23: Concluído | L23: 4. TI/DF-e
A24: 2.4 | B24: N | C24: Atualizar o eDocs e testar a NFS-e em produção restrita nos municípios de maior volume | D24: Pablo | E24: 46291 | F24: 46291 | G24: =IF(OR(E24="",F24=""),"",NETWORKDAYS(E24,F24,Feriados!$A$2:$A$9)) -> 0 | H24: 46291 | I24: 46291 | J24: Concluído | L24: 4. TI/DF-e
A25: 2.5 | B25: N | C25: Parametrizar os cadastros base: NBS, serviço, IndOp, cliente, fornecedor e transações | D25: Pablo e Kelvin | E25: 46286 | F25: 46293 | G25: =IF(OR(E25="",F25=""),"",NETWORKDAYS(E25,F25,Feriados!$A$2:$A$9)) -> 6 | H25: 46286 | I25: 46293 | J25: Concluído | L25: 4. TI/DF-e
A26: 2.6 | B26: N | C26: Parametrizar alíquotas e aplicação da CBS | D26: Pablo e Kelvin | E26: 46288 | F26: 46294 | G26: =IF(OR(E26="",F26=""),"",NETWORKDAYS(E26,F26,Feriados!$A$2:$A$9)) -> 5 | H26: 46294 | I26: 46294 | J26: Concluído | L26: 4. TI/DF-e
A27: 2.7 | B27: N | C27: Habilitar o cálculo da CBS e do IBS filial a filial | D27: Kelvin | E27: 46293 | F27: 46294 | G27: =IF(OR(E27="",F27=""),"",NETWORKDAYS(E27,F27,Feriados!$A$2:$A$9)) -> 2 | H27: 46293 | I27: 46294 | J27: Concluído | L27: 4. TI/DF-e
A28: 2.8 | B28: N | C28: Levantar e validar tela a tela o que já está parametrizado (Saída) | D28: Pablo e Kelvin | E28: 46293 | F28: 46295 | G28: =IF(OR(E28="",F28=""),"",NETWORKDAYS(E28,F28,Feriados!$A$2:$A$9)) -> 3 | H28: 46293 | I28: 46295 | J28: Concluído | L28: 4. TI/DF-e
A29: 2.9 | B29: N | C29: Criar e apresentar o norteador de parametrização por ondas (o que, quais campos, quem preenche, em quantos dias) | D29: Pablo e Kelvin | E29: 46293 | F29: 46296 | G29: =IF(OR(E29="",F29=""),"",NETWORKDAYS(E29,F29,Feriados!$A$2:$A$9)) -> 4 | H29: 46296 | I29: 46296 | J29: Concluído | L29: 4. TI/DF-e
A30: 2.10 | B30: N | C30: Avaliar custo e risco do ambiente de homologação espelhado à produção, ou propor outra estratégia para testar a virada | D30: Pablo e Kelvin | E30: 46296 | F30: 46296 | G30: =IF(OR(E30="",F30=""),"",NETWORKDAYS(E30,F30,Feriados!$A$2:$A$9)) -> 1 | H30: 46296 | I30: 46296 | J30: Concluído | L30: 4. TI/DF-e
A31: 2.11 | B31: N | C31: Testar o robo validador de cenários na Senior com as notas de agosto em diante | D31: Adilson Alberton | E31: 46307 | F31: 46311 | G31: =IF(OR(E31="",F31=""),"",NETWORKDAYS(E31,F31,Feriados!$A$2:$A$9)) -> 4 | H31: 46296 | I31: 46296 | J31: Concluído | L31: 3. Fiscal/CST
A32: 2.12 | B32: N | C32: Resolver a emissão de Lages (tag de informações do município no XML) ou escalar (Senior) | D32: Pablo e Kelvin | E32: 46295 | F32: 46300 | G32: =IF(OR(E32="",F32=""),"",NETWORKDAYS(E32,F32,Feriados!$A$2:$A$9)) -> 4 | H32: 46301 | I32: 46301 | J32: Concluído | L32: 4. TI/DF-e
A33: 2.13 | B33: S | C33: Acompanhar a emissão real das primeiras notas com IBS e CBS destacados | D33: Pablo e Kelvin | G33: =IF(OR(E33="",F33=""),"",NETWORKDAYS(E33,F33,Feriados!$A$2:$A$9)) | J33: Não iniciado | K33: Relatado que as notas já saem com IBS e CBS no XML. Confirmar para marcar como concluída | L33: 4. TI/DF-e
A34: 2.14 | B34: N | C34: Validar se o monitoramento atual de rejeições de DF-e (eDocs) atende como painel do KPI de taxa de rejeição e, se não atender, propor o painel | D34: Pablo e Kelvin | E34: 46308 | F34: 46318 | G34: =IF(OR(E34="",F34=""),"",NETWORKDAYS(E34,F34,Feriados!$A$2:$A$9)) -> 9 | J34: Não iniciado | L34: 4. TI/DF-e
A35: 2.15 | B35: N | C35: Validar se a contingência de emissão da NFS-e (ambiente nacional ou prefeitura fora do ar) já existe e foi testada e, se não, testar | D35: Pablo e Kelvin | E35: 46321 | F35: 46332 | G35: =IF(OR(E35="",F35=""),"",NETWORKDAYS(E35,F35,Feriados!$A$2:$A$9)) -> 9 | J35: Não iniciado | L35: 4. TI/DF-e
A36: 2.16 | B36: N | C36: Enviar a controladoria fiscal a tabela com os contratos e respectivos NBS (Saida) | D36: Andre Desoti | E36: 46300 | F36: 46308 | G36: =IF(OR(E36="",F36=""),"",NETWORKDAYS(E36,F36,Feriados!$A$2:$A$9)) -> 6 | H36: 46302 | J36: Em andamento | L36: 3. Fiscal/CST
A37: 2.17 | B37: N | C37: Cadastrar novos códigos de serviço no erp senior | D37: Robson Carvalho | E37: 46309 | F37: 46311 | G37: =IF(OR(E37="",F37=""),"",NETWORKDAYS(E37,F37,Feriados!$A$2:$A$9)) -> 3 | J37: Não iniciado | L37: 3. Fiscal/CST
C38: Realizar testes de emissão em homologação com os novos códigos de serviço | D38: Robson Carvalho | E38: 46321 | F38: 46325 | G38: =IF(OR(E38="",F38=""),"",NETWORKDAYS(E38,F38,Feriados!$A$2:$A$9)) -> 5
C39: Alterar os códigos de serviço para o faturamento | D39: Robson Carvalho com apoio do Kelvin | E39: 46384 | F39: 46384 | G39: =IF(OR(E39="",F39=""),"",NETWORKDAYS(E39,F39,Feriados!$A$2:$A$9)) -> 1
A40: 2.18 | B40: N | C40: Avaliar o documento criado pelo T.I (2.9) e trazer data do cadastro | D40: CRIAR POR ÁREA | E40: 46308 | F40: 46310 | G40: =IF(OR(E40="",F40=""),"",NETWORKDAYS(E40,F40,Feriados!$A$2:$A$9)) -> 3 | J40: Não iniciado | L40: 4. TI/DF-e
...

Sheet Cronograma
A1: Cronograma CBS 2027
A2: Reforma Tributária
A3: Última atualização | D3: 46290
E4: Previsto | H4: Real
A5: ID | B5: Marco | C5: Atividade | D5: Responsável | E5: Início | F5: Término | G5: Dias úteis | H5: Início | I5: Término | J5: Status | K5: Observação | L5: Frente
A6: 1 | B6: N | C6: Planejamento - Tarefa 101363 | E6: =MIN(E7:E19) -> 46286 | F6: =MAX(F7:F19) -> 46304 | G6: =IF(OR(E6="",F6=""),"",NETWORKDAYS(E6,F6,Feriados!$A$2:$A$9)) -> 15 | H6: =MIN(H7:H19) -> 46288 | I6: =MAX(I7:I19) -> 46297
A7: 1.1 | B7: S | C7: Confirmar a assinatura do contrato da JP Balaban | D7: Kairon Riguete | E7: 46296 | F7: 46304 | G7: =IF(OR(E7="",F7=""),"",NETWORKDAYS(E7,F7,Feriados!$A$2:$A$9)) -> 7 | J7: Não iniciado | L7: 9. Governança/PMO
A8: 1.2 | B8: N | C8: Realizar agendamento semanal de reuniões com os principais envolvidos | D8: Michael Albertoni | E8: 46290 | F8: 46290 | G8: =IF(OR(E8="",F8=""),"",NETWORKDAYS(E8,F8,Feriados!$A$2:$A$9)) -> 1 | H8: 46290 | I8: 46290 | J8: Concluído | L8: 9. Governança/PMO
A9: 1.3 | B9: S | C9: Validar cronograma com o Kairon | D9: Michael Albertoni | E9: 46286 | F9: 46304 | G9: =IF(OR(E9="",F9=""),"",NETWORKDAYS(E9,F9,Feriados!$A$2:$A$9)) -> 15 | J9: Não iniciado | L9: 9. Governança/PMO
A10: 1.4 | B10: N | C10: Revisar a escala de férias de fim de ano das pessoas chave | D10: Juliano Liberato | E10: 46296 | F10: 46304 | G10: =IF(OR(E10="",F10=""),"",NETWORKDAYS(E10,F10,Feriados!$A$2:$A$9)) -> 7 | J10: Não iniciado | K10: Considerar o conflito entre férias coletivas a partir de 20/12 e a virada de regime (levantado na reunião) A Eliandra não para na virada; de 18/11 a 30/11 atende só parcialmente | L10: 9. Governança/PMO
A11: 1.5 | B11: N | C11: Revisar cronograma com o dpto de controladoria e Fiscal | D11: Michael Albertoni | E11: 46288 | F11: 46288 | G11: =IF(OR(E11="",F11=""),"",NETWORKDAYS(E11,F11,Feriados!$A$2:$A$9)) -> 1 | H11: 46288 | I11: 46288 | J11: Concluído | L11: 9. Governança/PMO
A12: 1.6 | B12: N | C12: Revisar o cronograma com o dpto de contratos | D12: Michael Albertoni | E12: 46289 | F12: 46289 | G12: =IF(OR(E12="",F12=""),"",NETWORKDAYS(E12,F12,Feriados!$A$2:$A$9)) -> 1 | H12: 46289 | I12: 46289 | J12: Concluído | L12: 9. Governança/PMO
A13: 1.7 | B13: N | C13: Revisar o cronograma com o dpto Financeiro | D13: Michael Albertoni | E13: 46289 | F13: 46289 | G13: =IF(OR(E13="",F13=""),"",NETWORKDAYS(E13,F13,Feriados!$A$2:$A$9)) -> 1 | H13: 46289 | I13: 46289 | J13: Concluído | L13: 9. Governança/PMO
A14: 1.8 | B14: N | C14: Revisar o cronograma com o dpto Comercial | D14: Michael Albertoni | E14: 46302 | F14: 46304 | G14: =IF(OR(E14="",F14=""),"",NETWORKDAYS(E14,F14,Feriados!$A$2:$A$9)) -> 3 | J14: Não iniciado | L14: 9. Governança/PMO
A15: 1.9 | B15: N | C15: Revisar o cronograma com o dpto de RH | D15: Michael Albertoni | E15: 46302 | F15: 46304 | G15: =IF(OR(E15="",F15=""),"",NETWORKDAYS(E15,F15,Feriados!$A$2:$A$9)) -> 3 | J15: Não iniciado | L15: 9. Governança/PMO
A16: 1.10 | B16: N | C16: Revisar o cronograma com o dpto de Supply Chain (Suprimentos e Frotas) | D16: Michael Albertoni | E16: 46293 | F16: 46293 | G16: =IF(OR(E16="",F16=""),"",NETWORKDAYS(E16,F16,Feriados!$A$2:$A$9)) -> 1 | H16: 46293 | I16: 46293 | J16: Concluído | L16: 9. Governança/PMO
A17: 1.11 | B17: N | C17: Revisar o cronograma com o dpto de T.I | D17: Michael Albertoni | E17: 46293 | F17: 46293 | G17: =IF(OR(E17="",F17=""),"",NETWORKDAYS(E17,F17,Feriados!$A$2:$A$9)) -> 1 | H17: 46293 | I17: 46293 | J17: Concluído | L17: 9. Governança/PMO
A18: 1.12 | B18: N | C18: Revisar o cronograma com a Contabilidade | D18: Michael Albertoni | E18: 46295 | F18: 46295 | G18: =IF(OR(E18="",F18=""),"",NETWORKDAYS(E18,F18,Feriados!$A$2:$A$9)) -> 1 | H18: 46297 | I18: 46297 | J18: Concluído | L18: 9. Governança/PMO
A19: 1.13 | B19: N | C19: Revisar o cronograma com o Patrocinador e aprovar o painel mensal de KPIs ao Conselho (rejeição de DF-e, captura de créditos por categoria em R$ e %, claims protocolados e deferidos em 90 dias, aderência ao cronograma, desvio orçamentário e metas por empresa: CO, Grabin, Terceirize e Bogo) | D19: Michael Albertoni | E19: 46304 | F19: 46304 | G19: =IF(OR(E19="",F19=""),"",NETWORKDAYS(E19,F19,Feriados!$A$2:$A$9)) -> 1 | J19: Não iniciado | L19: 9. Governança/PMO
A20: 2 | C20: Parametrização do ERP Senior - Tarefa 102141 | E20: =MIN(E21:E56) -> 46286 | F20: =MAX(F21:F56) -> 46386 | G20: =IF(OR(E20="",F20=""),"",NETWORKDAYS(E20,F20,Feriados!$A$2:$A$9)) -> 69 | H20: =MIN(H21:H63) -> 46286 | I20: =MAX(I21:I63) -> 46301
A21: 2.1 | B21: N | C21: Confirmar a build do ERP, a versão do eDocs e o layout 2.00 da NFS-e | D21: Kelvin | E21: 46286 | F21: 46290 | G21: =IF(OR(E21="",F21=""),"",NETWORKDAYS(E21,F21,Feriados!$A$2:$A$9)) -> 5 | H21: 46286 | I21: 46290 | J21: Concluído | L21: 4. TI/DF-e
A22: 2.2 | B22: N | C22: Atualizar o ERP e o eDocs com a correção da Senior para as notas de devolução | D22: Pablo e Kelvin | E22: 46291 | F22: 46291 | G22: =IF(OR(E22="",F22=""),"",NETWORKDAYS(E22,F22,Feriados!$A$2:$A$9)) -> 0 | H22: 46291 | I22: 46291 | J22: Concluído | L22: 4. TI/DF-e
A23: 2.3 | B23: N | C23: Mapear os municípios de emissão e a situação de homologação com a Reforma | D23: Pablo | E23: 46286 | F23: 46290 | G23: =IF(OR(E23="",F23=""),"",NETWORKDAYS(E23,F23,Feriados!$A$2:$A$9)) -> 5 | H23: 46286 | I23: 46290 | J23: Concluído | L23: 4. TI/DF-e
A24: 2.4 | B24: N | C24: Levantar e validar tela a tela o que já está parametrizado (Saída) | D24: Pablo | E24: 46293 | F24: 46295 | G24: =IF(OR(E24="",F24=""),"",NETWORKDAYS(E24,F24,Feriados!$A$2:$A$9)) -> 3 | H24: 46293 | I24: 46295 | J24: Concluído | L24: 4. TI/DF-e
A25: 2.5 | B25: N | C25: Levantar e validar tela a tela o que já está parametrizado (Entrada) | D25: Pablo e Kelvin | E25: 46293 | F25: 46304 | G25: =IF(OR(E25="",F25=""),"",NETWORKDAYS(E25,F25,Feriados!$A$2:$A$9)) -> 10 | J25: Não iniciado | L25: 4. TI/DF-e
A26: 2.6 | B26: N | C26: Avaliar a migração das prefeituras de Lages para o ambiente nacional | D26: Kelvin | E26: 46301 | F26: 46301 | G26: =IF(OR(E26="",F26=""),"",NETWORKDAYS(E26,F26,Feriados!$A$2:$A$9)) -> 1 | H26: 46301 | I26: 46301 | J26: Concluído | L26: 4. TI/DF-e
A27: 2.7 | B27: N | C27: Resolver a emissão de Lages (tag de informações do município no XML) ou escalar (Senior) | D27: Pablo e Kelvin | E27: 46293 | F27: 46294 | G27: =IF(OR(E27="",F27=""),"",NETWORKDAYS(E27,F27,Feriados!$A$2:$A$9)) -> 2 | H27: 46295 | I27: 46295 | J27: Concluído | L27: 4. TI/DF-e
A28: 2.8 | B28: N | C28: Parametrizar os cadastros base: NBS, serviço, IndOp, cliente, fornecedor e transações | D28: Pablo | E28: 46286 | F28: 46293 | G28: =IF(OR(E28="",F28=""),"",NETWORKDAYS(E28,F28,Feriados!$A$2:$A$9)) -> 6 | H28: 46286 | I28: 46293 | J28: Concluído | L28: 4. TI/DF-e
A29: 2.9 | B29: N | C29: Enviar a controladoria fiscal a tabela com os contratos e respectivos NBS (Saida) | D29: Andre Desoti | E29: 46300 | F29: 46304 | G29: =IF(OR(E29="",F29=""),"",NETWORKDAYS(E29,F29,Feriados!$A$2:$A$9)) -> 5 | H29: 46302 | J29: Em andamento | L29: 3. Fiscal/CST
A30: 2.10 | B30: N | C30: Validar os cadastros base de NBS, serviço e IndOP (Saida) | D30: Adilson Alberton | E30: 46307 | F30: 46311 | G30: =IF(OR(E30="",F30=""),"",NETWORKDAYS(E30,F30,Feriados!$A$2:$A$9)) -> 4 | J30: Não iniciado | L30: 3. Fiscal/CST
A31: 2.11 | B31: S | C31: Avaliar quem ira validar a base de NBS, serviço e IndOP na entrada | D31: Kairon Riguete | E31: 46314 | F31: 46324 | G31: =IF(OR(E31="",F31=""),"",NETWORKDAYS(E31,F31,Feriados!$A$2:$A$9)) -> 9 | J31: Não iniciado | L31: 3. Fiscal/CST
A32: 2.12 | B32: N | C32: Validar fornecedor | D32: Fernando Gomes | E32: 46325 | F32: 46339 | G32: =IF(OR(E32="",F32=""),"",NETWORKDAYS(E32,F32,Feriados!$A$2:$A$9)) -> 10 | J32: Não iniciado | L32: Suprimentos
A33: 2.13 | B33: N | C33: Validar transações | D33: Juliano Liberato | E33: 46296 | F33: 46325 | G33: =IF(OR(E33="",F33=""),"",NETWORKDAYS(E33,F33,Feriados!$A$2:$A$9)) -> 21 | J33: Não iniciado | L33: 3. Fiscal/CST
A34: 2.14 | B34: N | C34: Parametrizar alíquotas e aplicação da CBS | D34: Kelvin | E34: 46288 | F34: 46294 | G34: =IF(OR(E34="",F34=""),"",NETWORKDAYS(E34,F34,Feriados!$A$2:$A$9)) -> 5 | H34: 46294 | I34: 46294 | J34: Concluído | L34: 4. TI/DF-e
A35: 2.15 | B35: S | C35: Enviar à Controladoria (Adilson) a alíquota oficial de CBS assim que for publicada | D35: Eliandra Fraron | E35: 46371 | F35: 46374 | G35: =IF(OR(E35="",F35=""),"",NETWORKDAYS(E35,F35,Feriados!$A$2:$A$9)) -> 4 | J35: Não iniciado | K35: Publicação prevista até 15/12 (Senado); a Eliandra acha que pode sair dia 20. Informação pública: a Controladoria também pode pegar direto | L35: 5. Contábil
A36: 2.16 | B36: N | C36: Informar o valor correto de aplicação CBS na senior | D36: Adilson Alberton | E36: 46374 | F36: 46374 | G36: =IF(OR(E36="",F36=""),"",NETWORKDAYS(E36,F36,Feriados!$A$2:$A$9)) -> 1 | J36: Não iniciado | L36: 3. Fiscal/CST
A37: 2.17 | B37: N | C37: Validar na emissão da nota se a alíquota cadastrada pelo Adilson está saindo correta | D37: Eliandra Fraron | E37: 46377 | F37: 46379 | G37: =IF(OR(E37="",F37=""),"",NETWORKDAYS(E37,F37,Feriados!$A$2:$A$9)) -> 3 | J37: Não iniciado | K37: Eliandra (02/10): IBS, CBS e cClassTrib já enviados pela Contabilidade à Controladoria | L37: 5. Contábil
A38: 2.18 | B38: N | C38: Parametrizar o cClassTrib e zerar os cenários abertos no analisador | D38: Giselle | E38: 46300 | F38: 46311 | G38: =IF(OR(E38="",F38=""),"",NETWORKDAYS(E38,F38,Feriados!$A$2:$A$9)) -> 9 | J38: Não iniciado | K38: Depende da 7.3 (lista de cClassTrib por cliente, do Contratos) | L38: 3. Fiscal/CST
A39: 2.19 | B39: N | C39: Habilitar o cálculo da CBS e do IBS filial a filial | D39: Kelvin | E39: 46293 | F39: 46294 | G39: =IF(OR(E39="",F39=""),"",NETWORKDAYS(E39,F39,Feriados!$A$2:$A$9)) -> 2 | H39: 46293 | I39: 46294 | J39: Concluído | L39: 4. TI/DF-e
A40: 2.20 | B40: N | C40: Atualizar o eDocs e testar a NFS-e em produção restrita nos municípios de maior volume | D40: Pablo | E40: 46291 | F40: 46291 | G40: =IF(OR(E40="",F40=""),"",NETWORKDAYS(E40,F40,Feriados!$A$2:$A$9)) -> 0 | H40: 46291 | I40: 46291 | J40: Concluído | L40: 4. TI/DF-e
...

Sheet Alterações 24-09
A1: Alterações da reunião com Controladoria/Fiscal (24/09/2026)
A2: DITO = decidido na reunião (fala ou edição feita na planilha durante a reunião). INFERIDO = ajuste feito na organização do arquivo, validar.
A4: ID novo | B4: ID anterior | C4: Tipo | D4: O que mudou | E4: Base
A5: 1.2 | B5: 1.2 | C5: Alterada | D5: Correção de texto: "reunões" para "reuniões" | E5: DITO
A6: 2.2 | B6: 2.2 | C6: Alterada | D6: DeRE retirada; mantida só a cobrança das APIs de apuração da CBS (saem entre outubro e novembro) | E6: DITO
A7: 2.4 | B7: 2.4 | C7: Alterada | D7: Registrado que o único problema é Medianeira (Bogo Locações), a ver com a T.I. | E7: DITO
A8: 2.8 | C8: Incluída | D8: Validar a parametrização do item 2.7. Responsável: Eliandra Fraron. Datas a definir | E8: DITO
A9: 2.9 | B9: 2.8 | C9: Alterada | D9: Passa a depender da lista de cClassTrib por cliente (7.2) | E9: DITO
A10: 2.12 | B10: 2.11 | C10: Alterada | D10: Robô diagnóstico identificado como ferramenta da Senior; ver acesso com a T.I. | E10: DITO
A11: 2.16 | B11: 2.15 | C11: Alterada | D11: Responsável: Giselle para Adilson Alberton | E11: DITO
A12: 2.17 | B12: 2.16 | C12: Alterada | D12: Retirada a "DeRE 2/2" das entregas Senior de novembro | E12: DITO
A13: 2.18 | B13: 2.17 | C13: Alterada | D13: Responsável: Kelvin para Eliandra Fraron | E13: DITO
A14: 2.19 | C14: Incluída | D14: Validar a integração contábil (2.18) com nota de teste. Responsável: Juliano Liberato. Datas a definir | E14: DITO
A15: 2.20 | B15: 2.18 | C15: Alterada | D15: Responsável: Kelvin para Eliandra Fraron. Marcada para confirmar | E15: DITO
A16: 2.3, 2.11, 2.13 | B16: 2.3, 2.10, 2.12 | C16: Status a confirmar | D16: Relatadas como já realizadas (eDocs na última versão, notas saindo com IBS e CBS). Status não alterado até confirmação | E16: DITO
A17: 3.2 | B17: 3.2 | C17: Alterada | D17: Incluída "nova transação e forma de contabilização". Responsável: Kelvin para Adilson Alberton | E17: DITO
A18: 3.3 | B18: 3.3 | C18: Alterada | D18: Responsável: Giselle para Adilson Alberton. Dito que o mês fechado do paralelo é janeiro (datas a revisar) | E18: DITO
A19: 7.13 | B19: 3.4 | C19: Movida | D19: Acompanhar o primeiro faturamento no novo regime foi para Comercial e Contratos | E19: DITO
A20: Removida | B20: 4.1 | C20: Removida | D20: Parecer sobre a DeRE: a DeRE não se aplica ao Grupo | E20: DITO
A21: 4.1 | B21: 4.2 | C21: Alterada | D21: Registrada a dependência da lista de créditos (4.3) | E21: DITO
A22: Removida | B22: 4.5 | C22: Removida | D22: Inconsistências de PIS e Cofins apontadas pela Receita: rotina, não é do projeto | E22: DITO
A23: Removida | B23: 4.6 | C23: Removida | D23: Política contábil de 2026 com a auditoria | E23: DITO
A24: Removida | B24: 4.8 | C24: Removida | D24: Centros de custo de merenda e refeição corporativa: já resolvido | E24: DITO
A25: 4.5 | B25: 4.9 | C25: A confirmar | D25: Contas de IBS e CBS provavelmente já abertas no plano de contas | E25: DITO
A26: Removida | B26: 4.11 | C26: Removida | D26: Mapear editais com exigência de índices ou faturamento mínimo | E26: DITO
... A34: 7.1 | B34: 7.1 | C34: Alterada | D34: Responsável: André Desoti para Clayton. Ordem 1 | E34: DITO
A35: 7.2 | C35: Incluída | D35: Lista de cClassTrib por serviço e por cliente (todos). André Desoti. Urgente (ordem 1.1) | E35: DITO
A36: 7.3 | B36: 7.4 | C36: Alterada | D36: Responsável: Ingrid Perez para André Desoti. Confirmar se é o mesmo documento da 7.4 | E36: DITO
A37: 7.4 | C37: Incluída | D37: Preparar o modelo de pedido de reequilíbrio para contratos públicos. André Desoti | E37: DITO
A38: 7.7 | B38: 7.8 | C38: Alterada | D38: De "pilotos de 5 a 10 contratos" para todos os contratos | E38: DITO
A39: 7.9 | B39: 7.2 | C39: Alterada | D39: De "clientes privados" para 100% dos clientes; passa a vir depois do protocolo | E39: DITO
A40: 7.10 | B40: 7.6 | C40: Alterada | D40: De "assinar os aditivos dos clientes privados" para monitorar a assinatura de aditivos e reequilíbrios de 100% dos clientes | E40: DITO
A41: 7.11 | C41: Incluída | D41: Avaliar antecipar o faturamento para dezembro. Kairon Riguete | E41: DITO
A42: 7.12 | C42: Incluída | D42: Validar as alíquotas de CBS com o faturamento antes do início do faturamento de 01/2027. André Desoti | E42: DITO
A43: 7.14 | B43: 7.5 | C43: Reordenada | D43: Simulação da carteira marcada como n/a na ordem. Confirmar se sai | E43: DITO
A44: Seção 7 | B44: Seção 7 | C44: Reordenada | D44: Seção reordenada pela sequência definida na reunião (coluna Observação traz a ordem) | E44: DITO

Sheet Marcos externos
A1: Marcos externos
A2: Datas definidas por lei, ato normativo ou fornecedor, fora do controle do projeto
A4: ID | B4: Data | C4: Marco | D4: Fonte | E4: Quem define | F4: Atividades vinculadas | G4: Dias até o marco
A5: E01 | B5: 46295 | C5: Fim da janela de opção pelo Simples e pelo regime regular de IBS e CBS para o 1º semestre de 2027 | D5: Resoluções CGSN 190 e 191/2026 | E5: Fornecedores do Simples | F5: S03 | G5: =IF(B5<#REF!,"Passado",B5-#REF!) -> #REF!
A6: E02 | B6: 46296 | C6: NFS-e com destaque obrigatório de IBS e CBS | D6: Ato Conjunto RFB/CGIBS nº 4/2026 | E6: Receita Federal e CGIBS | F6: T11, T12, T13 | G6: =IF(B6<#REF!,"Passado",B6-#REF!) -> #REF!
A7: E03 | B7: 46296 | C7: DeRE passa a receber os eventos de tabela do contribuinte | D7: Comunicado SPED | E7: Receita Federal | F7: Não se aplica (DeRE fora do escopo) | G7: =IF(B7<#REF!,"Passado",B7-#REF!) -> #REF!
A8: E04 | B8: 46300 | C8: API de apuração da CBS: consulta de débitos e créditos (início de outubro) | D8: Documentação técnica RFB de 14/09/2026 | E8: Receita Federal | F8: T02 | G8: =IF(B8<#REF!,"Passado",B8-#REF!) -> #REF!
A9: E05 | B9: 46325 | C9: Publicação dos leiautes de nota de débito e nota de crédito (previsão) | D9: Reunião de TI | E9: Receita Federal e CGIBS | F9: T15 | G9: =IF(B9<#REF!,"Passado",B9-#REF!) -> #REF!
A10: E06 | B10: 46325 | C10: Cálculos do TCU encaminhados ao Senado | D10: Prazos da alíquota de referência prorrogados em 45 dias | E10: TCU | G10: =IF(B10<#REF!,"Passado",B10-#REF!) -> #REF!
A11: E07 | B11: 46329 | C11: API de apuração da CBS: pagamentos e recolhimentos pelo adquirente (início de novembro) | D11: Documentação técnica RFB de 14/09/2026 | E11: Receita Federal | G11: =IF(B11<#REF!,"Passado",B11-#REF!) -> #REF!
A12: E08 | B12: 46336 | C12: Prazo para correção das inconsistências de PIS e Cofins apontadas pela Receita | D12: Memorando Contábil 18/09 | E12: Receita Federal | F12: Atividade removida na reunião | G12: =IF(B12<#REF!,"Passado",B12-#REF!) -> #REF!
A13: E09 | B13: 46339 | C13: Primeira entrega mensal da DeRE, competência outubro (prazo legal 15/11, domingo) | D13: Comunicado SPED | E13: Receita Federal | F13: Não se aplica (DeRE fora do escopo) | G13: =IF(B13<#REF!,"Passado",B13-#REF!) -> #REF!
A14: E10 | B14: 46356 | C14: Prazo para o fornecedor cancelar a opção feita em setembro | D14: Resoluções CGSN 190 e 191/2026 | E14: Fornecedores do Simples | F14: S05 | G14: =IF(B14<#REF!,"Passado",B14-#REF!) -> #REF!
A15: E11 | B15: 46356 | C15: Entregas Senior de novembro: split payment, conciliação da apuração, DeRE 2/2 | D15: Calendário de liberações Senior | E15: Senior | F15: T17 | G15: =IF(B15<#REF!,"Passado",B15-#REF!) -> #REF!
A16: E12 | B16: 46356 | C16: API de apuração da CBS: emissão de DARF RAD e PCONT (fim de novembro) | D16: Documentação técnica RFB de 14/09/2026 | E16: Receita Federal | F16: F02 | G16: =IF(B16<#REF!,"Passado",B16-#REF!) -> #REF!
A17: E13 | B17: 46357 | C17: Segunda onda da NFS-e, incluindo locações | D17: Ato Conjunto RFB/CGIBS nº 4/2026 | E17: Receita Federal e CGIBS | F17: T16 | G17: =IF(B17<#REF!,"Passado",B17-#REF!) -> #REF!
A18: E14 | B18: 46371 | C18: Prazo máximo para definição da alíquota de referência pelo Senado | D18: Prazos da alíquota de referência prorrogados em 45 dias | E18: Senado Federal | F18: T20, K06 | G18: =IF(B18<#REF!,"Passado",B18-#REF!) -> #REF!
A19: E15 | B19: 46387 | C19: Fim do PIS e da Cofins e fim da tolerância de não rejeição da NFS-e sem IBS e CBS | D19: LC 214/2025 e Ato Conjunto RFB/CGIBS nº 4/2026 | E19: Receita Federal | F19: K13 | G19: =IF(B19<#REF!,"Passado",B19-#REF!) -> #REF!
A20: E16 | B20: 46447 | C20: Nova janela de opção do Simples, com efeito no 2º semestre de 2027 | D20: Resoluções CGSN 190 e 191/2026 | E20: Fornecedores do Simples | F20: S09 | G20: =IF(B20<#REF!,"Passado",B20-#REF!) -> #REF!
A21: E17 | B21: 46569 | C21: Split payment facultativo, somente entre empresas (informado na reunião como prorrogado para 2028; confirmar o ato) | D21: Memorando ERP 18/09 | E21: Receita Federal e CGIBS | F21: F08 | G21: =IF(B21<#REF!,"Passado",B21-#REF!) -> #REF!

Sheet Premissas
A1: Premissas
A3: Nº | B3: Premissa
A4: 1 | B4: Datas legais conforme os atos publicados até 18/09/2026.
A5: 2 | B5: Datas internas propostas, sujeitas à validação com Kairon Riguete.
A6: 3 | B6: Prazos que caíam em fim de semana ou feriado foram antecipados para o dia útil anterior.
A7: 4 | B7: Reunião semanal de status às sextas-feiras, com as principais lideranças.
A8: 5 | B8: Equipe de TI e Controladoria trabalhando em sala dedicada, em blocos diários.
A9: 6 | B9: Melhorias e customizações de TI suspensas; suporte à operação e ao faturamento mantidos.
A10: 7 | B10: Fechamento de dezembro de 2026 no regime atual; novo regime aplicado a partir da virada.
A11: 8 | B11: Split payment informado na reunião de 24/09 como prorrogado para 2028 (confirmar o ato); fora do horizonte deste cronograma.
A12: 9 | B12: Automação da separação de documentos por cliente tratada no projeto de IA corporativa.
A13: 10 | B13: Contrato da JP Balaban pendente de assinatura; atividades da consultoria condicionadas à assinatura.
A14: 11 | B14: Horizonte do cronograma: 21/09/2026 a 31/03/2027.
A15: 12 | B15: DeRE não se aplica às empresas do Grupo (decisão da reunião de 24/09).
A16: 13 | B16: Datas das atividades novas ou sem data serão confirmadas com cada área responsável.

Sheet Feriados
A1: Data | B1: Feriado
A2: 46307 | B2: Nossa Senhora Aparecida
A3: 46328 | B3: Finados
A4: 46341 | B4: Proclamação da República
A5: 46346 | B5: Dia da Consciência Negra
A6: 46381 | B6: Natal
A7: 46388 | B7: Confraternização Universal
A8: 46433 | B8: Carnaval
A9: 46434 | B9: Carnaval
